Workbook

Sheet Sheet3
C1: CENPK_1_EXP | D1: CENPK_2_EXP | E1: CENPK_3_EXP | F1: CENPK_1_ETH | G1: CENPK_2_ETH | H1: CENPK_3_ETH | I1: NER_1_72h | J1: NER_2_72h | K1: NER_3_72h | L1: NER_1_96h | M1: NER_2_96h | N1: NER_3_96h | O1: NERg_1_72h | P1: NERg_2_72h | Q1: NERg_3_72h | R1: NERg_1_96h | S1: NERg_2_96h | T1: NERg_3_96h | U1: NERgE_1_72h | V1: NERgE_2_72h | W1: NERgE_3_72h | X1: NERgE_1_96h | Y1: NERgE_2_96h | Z1: NERgE_3_96h | AA1: VAL_1_72h | AB1: VAL_2_72h | AC1: VAL_3_72h | AD1: VAL_1_96h | AE1: VAL_2_96h | AF1: VAL_3_96h | AG1: VALg_1_72h | AH1: VALg_2_72h | AI1: VALg_3_72h | AJ1: VALg_1_96h | AK1: VALg_2_96h | AL1: VALg_3_96h | AM1: HUMg_1_EXP | AN1: HUMg_2_EXP | AO1: HUMg_3_EXP | AP1: HUMgE_1_EXP | AQ1: HUMgE_2_EXP | AR1: HUMgE_3_EXP | AS1: HUMgE_1_ETH | AT1: HUMgE_2_ETH | AU1: HUMgE_3_ETH | AV1: HUMgE_1_72h | AW1: HUMgE_2_72h | AX1: HUMgE_3_72h | AY1: HUMgE_1_96h | AZ1: HUMgE_2_96h | BA1: HUMgE_3_96h | BB1: HUMgEh_1_EXP | BC1: HUMgEh_2_EXP | BD1: HUMgEh_3_EXP | BE1: HUMgEhE_1_EXP | BF1: HUMgEhE_2_EXP | BG1: HUMgEhE_3_EXP | BH1: HUMgEhE_1_ETH | BI1: HUMgEhE_2_ETH | BJ1: HUMgEhE_3_ETH | BK1: HUMgEhE_1_72h | BL1: HUMgEhE_2_72h | BM1: HUMgEhE_3_72h | BN1: HUMgEhE_1_96h | BO1: HUMgEhE_2_96h | BP1: HUMgEhE_3_96h | BQ1: LIMg_1_72h | BR1: LIMg_2_72h | BS1: LIMg_3_72h | BT1: LIMg_1_96h | BU1: LIMg_2_96h | BV1: LIMg_3_96h
A2: 1.1 | B2: HXT1 | C2: 204.51169 | D2: 251.76499 | E2: 299.01829 | F2: 0 | G2: 0 | H2: 0 | I2: -44.009784 | J2: 60.118483 | K2: 164.24675 | L2: -84.71704 | M2: 115.72563 | N2: 316.1683 | O2: 0 | P2: 0 | Q2: 0 | R2: -45.775575 | S2: 62.530598 | T2: 170.83677 | U2: 0 | V2: 0 | W2: 0 | X2: -21.952928 | Y2: 29.988258 | Z2: 81.929444 | AA2: 289.45426 | AB2: 359.34922 | AC2: 429.24417 | AD2: 303.38493 | AE2: 378.39408 | AF2: 453.40323 | AG2: 394.31522 | AH2: 448.82894 | AI2: 503.34266 | AJ2: 246.17376 | AK2: 353.31957 | AL2: 460.46539 | AM2: 148.68883 | AN2: 273.16392 | AO2: 397.63901 | AP2: 0 | AQ2: 0 | AR2: 0 | AS2: 0 | AT2: 0 | AU2: 0 | AV2: 0 | AW2: 0 | AX2: 0 | AY2: 0 | AZ2: 0 | BA2: 0 | BB2: -38.376494 | BC2: 52.423266 | BD2: 143.22303 | BE2: 0 | BF2: 0 | BG2: 0 | BH2: 0 | BI2: 0 | BJ2: 0 | BK2: -10.536439 | BL2: 14.393043 | BM2: 39.322526 | BN2: 0 | BO2: 0 | BP2: 0 | BQ2: 0 | BR2: 0 | BS2: 0 | BT2: 0 | BU2: 0 | BV2: 0
A3: 1.2
A4: 1.3
A5: 1.4
A6: 2.1 | B6: HXT2 | C6: 48.648133 | D6: 59.659029 | E6: 70.669925 | F6: 24.717593 | G6: 37.739009 | H6: 50.760426 | I6: 76.9948 | J6: 86.886682 | K6: 96.778565 | L6: 33.150849 | M6: 81.273091 | N6: 129.39533 | O6: 21.673666 | P6: 29.723328 | Q6: 37.77299 | R6: 13.12194 | S6: 26.568689 | T6: 40.015439 | U6: 23.101594 | V6: 32.569465 | W6: 42.037335 | X6: 24.117067 | Y6: 32.79338 | Z6: 41.469694 | AA6: 39.31734 | AB6: 65.77888 | AC6: 92.24042 | AD6: 30.274016 | AE6: 31.213996 | AF6: 32.153977 | AG6: 17.297532 | AH6: 35.181708 | AI6: 53.065885 | AJ6: 4.0562377 | AK6: 31.728172 | AL6: 59.400107 | AM6: 157.55821 | AN6: 181.44303 | AO6: 205.32785 | AP6: 321.99507 | AQ6: 408.50088 | AR6: 495.0067 | AS6: 62.784541 | AT6: 63.690868 | AU6: 64.597195 | AV6: 15.502828 | AW6: 17.519952 | AX6: 19.537075 | AY6: 12.796062 | AZ6: 24.747721 | BA6: 36.69938 | BB6: 55.341659 | BC6: 158.24414 | BD6: 261.14661 | BE6: 370.9548 | BF6: 404.5454 | BG6: 438.13601 | BH6: 183.40913 | BI6: 235.37241 | BJ6: 287.33568 | BK6: 154.14608 | BL6: 176.29131 | BM6: 198.43653 | BN6: 108.35082 | BO6: 140.94398 | BP6: 173.53714 | BQ6: 17.808973 | BR6: 23.615915 | BS6: 29.422857 | BT6: 11.977355 | BU6: 13.968968 | BV6: 15.960581
A7: 2.2
A8: 2.3
A9: 2.4
A10: 3.1 | B10: HXT3 | C10: 76.914903 | D10: 81.182226 | E10: 85.449548 | F10: 18.509349 | G10: 24.437712 | H10: 30.366075 | I10: 220.09613 | J10: 265.19689 | K10: 310.29766 | L10: 134.76125 | M10: 261.47164 | N10: 388.18202 | O10: 22.54549 | P10: 71.902265 | Q10: 121.25904 | R10: 30.860971 | S10: 51.374871 | T10: 71.888771 | U10: 67.826884 | V10: 87.674002 | W10: 107.52112 | X10: 42.278365 | Y10: 61.257713 | Z10: 80.237062 | AA10: 366.47714 | AB10: 481.86492 | AC10: 597.25271 | AD10: 190.66402 | AE10: 288.10522 | AF10: 385.54642 | AG10: 95.27141 | AH10: 103.36191 | AI10: 111.45241 | AJ10: 55.509069 | AK10: 61.271652 | AL10: 67.034236 | AM10: 59.110171 | AN10: 71.05307 | AO10: 82.995969 | AP10: 36.904461 | AQ10: 45.632524 | AR10: 54.360586 | AS10: -6.2751597 | AT10: 13.272903 | AU10: 32.820966 | AV10: 1.2103245 | AW10: 36.105411 | AX10: 71.000497 | AY10: 0.41763931 | AZ10: 7.4648901 | BA10: 14.512141 | BB10: 92.61711 | BC10: 101.80664 | BD10: 110.99618 | BE10: 91.054782 | BF10: 112.23934 | BG10: 133.42389 | BH10: 56.182511 | BI10: 61.448163 | BJ10: 66.713814 | BK10: 16.348732 | BL10: 23.438472 | BM10: 30.528212 | BN10: 32.079343 | BO10: 36.36415 | BP10: 40.648956 | BQ10: 23.737626 | BR10: 29.657572 | BS10: 35.577519 | BT10: 12.192645 | BU10: 22.415833 | BV10: 32.639021
A11: 3.2
A12: 3.3
A13: 3.4
A14: 4.1 | B14: HXT4 | C14: 70.91079 | D14: 75.811643 | E14: 80.712496 | F14: -11.252874 | G14: 24.853552 | H14: 60.959979 | I14: 100.43082 | J14: 124.4074 | K14: 148.38398 | L14: 68.207738 | M14: 175.14662 | N14: 282.08549 | O14: 39.042794 | P14: 54.18848 | Q14: 69.334167 | R14: 7.6467786 | S14: 34.398196 | T14: 61.149614 | U14: 39.277881 | V14: 67.6159 | W14: 95.95392 | X14: -15.726632 | Y14: 21.482979 | Z14: 58.69259 | AA14: 182.75981 | AB14: 243.58393 | AC14: 304.40805 | AD14: 111.53158 | AE14: 131.07569 | AF14: 150.61979 | AG14: 59.413456 | AH14: 71.110492 | AI14: 82.807528 | AJ14: 29.118784 | AK14: 30.603914 | AL14: 32.089045 | AM14: 131.52568 | AN14: 164.09176 | AO14: 196.65783 | AP14: 84.664626 | AQ14: 103.38199 | AR14: 122.09935 | AS14: 1.9740001 | AT14: 15.359751 | AU14: 28.745503 | AV14: 23.22073 | AW14: 64.640297 | AX14: 106.05986 | AY14: 13.779977 | AZ14: 21.723016 | BA14: 29.666055 | BB14: 142.17103 | BC14: 163.03225 | BD14: 183.89347 | BE14: 341.73005 | BF14: 410.80779 | BG14: 479.88553 | BH14: 131.97086 | BI14: 137.12375 | BJ14: 142.27663 | BK14: 44.136144 | BL14: 46.468664 | BM14: 48.801184 | BN14: 119.87347 | BO14: 137.97229 | BP14: 156.07112 | BQ14: 46.923791 | BR14: 52.121945 | BS14: 57.3201 | BT14: 26.278607 | BU14: 28.99771 | BV14: 31.716813
A15: 4.2
A16: 4.3
A17: 4.4
A18: 5.1 | B18: HXT5 | C18: 0 | D18: 0 | E18: 0 | F18: 72.712086 | G18: 96.940713 | H18: 121.16934 | I18: 174.90962 | J18: 259.3827 | K18: 343.85577 | L18: 53.276979 | M18: 97.509631 | N18: 141.74228 | O18: 49.052266 | P18: 124.51453 | Q18: 199.9768 | R18: 51.694195 | S18: 82.623092 | T18: 113.55199 | U18: 178.37044 | V18: 261.41531 | W18: 344.46018 | X18: 31.010272 | Y18: 69.938104 | Z18: 108.86594 | AA18: 36.549468 | AB18: 41.603547 | AC18: 46.657626 | AD18: 0.6430057 | AE18: 5.3444454 | AF18: 10.045885 | AG18: 19.576798 | AH18: 22.869813 | AI18: 26.162829 | AJ18: 22.413737 | AK18: 24.232878 | AL18: 26.052019 | AM18: 11.288068 | AN18: 14.538062 | AO18: 17.788055 | AP18: 32.811534 | AQ18: 37.154788 | AR18: 41.498042 | AS18: -4.1710168 | AT18: 180.64711 | AU18: 365.46523 | AV18: 51.924249 | AW18: 106.74687 | AX18: 161.5695 | AY18: 46.224013 | AZ18: 59.595927 | BA18: 72.967841 | BB18: 6.5511616 | BC18: 13.248578 | BD18: 19.945994 | BE18: 6.0646095 | BF18: 14.752472 | BG18: 23.440335 | BH18: 127.96373 | BI18: 230.12623 | BJ18: 332.28872 | BK18: 370.49704 | BL18: 389.46945 | BM18: 408.44186 | BN18: 57.234453 | BO18: 65.51868 | BP18: 73.802907 | BQ18: 109.67982 | BR18: 120.66187 | BS18: 131.64392 | BT18: 76.688696 | BU18: 81.165204 | BV18: 85.641712
A19: 5.2
A20: 5.3
A21: 5.4
A22: 6.1 | B22: HXT6 | C22: 0 | D22: 0 | E22: 0 | F22: -0.77867727 | G22: 3.7877519 | H22: 8.3541812 | I22: 42.463768 | J22: 61.032882 | K22: 79.601995 | L22: 19.671664 | M22: 40.698988 | N22: 61.726313 | O22: -1.2705752 | P22: 1.735638 | Q22: 4.7418511 | R22: 0.85464506 | S22: 6.4930973 | T22: 12.13155 | U22: 1.8916577 | V22: 14.13429 | W22: 26.376923 | X22: -0.42878468 | Y22: 0.58573077 | Z22: 1.6002462 | AA22: 75.74922 | AB22: 218.58068 | AC22: 361.41213 | AD22: 19.36407 | AE22: 57.459492 | AF22: 95.554914 | AG22: 0 | AH22: 0 | AI22: 0 | AJ22: 0 | AK22: 0 | AL22: 0 | AM22: 8.8378789 | AN22: 12.580469 | AO22: 16.32306 | AP22: 212.25097 | AQ22: 365.66314 | AR22: 519.0753 | AS22: -36.844398 | AT22: 74.93704 | AU22: 186.71848 | AV22: 29.356056 | AW22: 55.184949 | AX22: 81.013843 | AY22: -3.6095688 | AZ22: 18.634903 | BA22: 40.879374 | BB22: 0.57793631 | BC22: 5.135431 | BD22: 9.6929258 | BE22: 75.635906 | BF22: 220.14468 | BG22: 364.65346 | BH22: 240.46215 | BI22: 510.30736 | BJ22: 780.15256 | BK22: 487.56655 | BL22: 574.56862 | BM22: 661.5707 | BN22: 70.692703 | BO22: 83.77604 | BP22: 96.859376 | BQ22: 15.792805 | BR22: 21.861576 | BS22: 27.930346 | BT22: 45.152406 | BU22: 52.697245 | BV22: 60.242085
A23: 6.2
A24: 6.3
A25: 6.4
A26: 7.1 | B26: HXT7 | C26: 0 | D26: 0 | E26: 0 | F26: -0.57768729 | G26: 0.78913551 | H26: 2.1559583 | I26: 35.184735 | J26: 44.633166 | K26: 54.081596 | L26: 13.749028 | M26: 24.93879 | N26: 36.128552 | O26: -1.9332041 | P26: 2.6408059 | Q26: 7.2148158 | R26: 1.8795248 | S26: 6.9249128 | T26: 11.970301 | U26: 6.4506923 | V26: 8.4039156 | W26: 10.357139 | X26: -1.4948393 | Y26: 2.0419885 | Z26: 5.5788163 | AA26: 69.810459 | AB26: 149.36115 | AC26: 228.91185 | AD26: 18.754109 | AE26: 41.021921 | AF26: 63.289732 | AG26: -2.0100492 | AH26: 2.7457783 | AI26: 7.5016059 | AJ26: 0 | AK26: 0 | AL26: 0 | AM26: 53.210173 | AN26: 76.039058 | AO26: 98.867944 | AP26: 459.10156 | AQ26: 570.60132 | AR26: 682.10109 | AS26: -12.491611 | AT26: 38.665336 | AU26: 89.822283 | AV26: 16.936631 | AW26: 36.201364 | AX26: 55.466098 | AY26: 9.5448018 | AZ26: 17.829207 | BA26: 26.113611 | BB26: 30.554312 | BC26: 50.746252 | BD26: 70.938191 | BE26: 226.58184 | BF26: 418.95927 | BG26: 611.3367 | BH26: 226.18249 | BI26: 327.77615 | BJ26: 429.36982 | BK26: 301.32544 | BL26: 366.85965 | BM26: 432.39386 | BN26: 148.59464 | BO26: 179.53678 | BP26: 210.47892 | BQ26: 12.515887 | BR26: 15.915567 | BS26: 19.315248 | BT26: 10.968861 | BU26: 17.368479 | BV26: 23.768097
A27: 7.2
A28: 7.3
A29: 7.4
A30: 8.1 | B30: HXT8 | C30: #N/A | D30: #N/A | E30: #N/A | F30: #N/A | G30: #N/A | H30: #N/A | I30: #N/A | J30: #N/A | K30: #N/A | L30: #N/A | M30: #N/A | N30: #N/A | O30: #N/A | P30: #N/A | Q30: #N/A | R30: #N/A | S30: #N/A | T30: #N/A | U30: #N/A | V30: #N/A | W30: #N/A | X30: #N/A | Y30: #N/A | Z30: #N/A | AA30: #N/A | AB30: #N/A | AC30: #N/A | AD30: #N/A | AE30: #N/A | AF30: #N/A | AG30: #N/A | AH30: #N/A | AI30: #N/A | AJ30: #N/A | AK30: #N/A | AL30: #N/A | AM30: #N/A | AN30: #N/A | AO30: #N/A | AP30: #N/A | AQ30: #N/A | AR30: #N/A | AS30: #N/A | AT30: #N/A | AU30: #N/A | AV30: #N/A | AW30: #N/A | AX30: #N/A | AY30: #N/A | AZ30: #N/A | BA30: #N/A | BB30: #N/A | BC30: #N/A | BD30: #N/A | BE30: #N/A | BF30: #N/A | BG30: #N/A | BH30: #N/A | BI30: #N/A | BJ30: #N/A | BK30: #N/A | BL30: #N/A | BM30: #N/A | BN30: #N/A | BO30: #N/A | BP30: #N/A | BQ30: #N/A | BR30: #N/A | BS30: #N/A | BT30: #N/A | BU30: #N/A | BV30: #N/A
A31: 8.2
A32: 8.3
A33: 8.4
A34: 9.1 | B34: HXT10 | C34: #N/A | D34: #N/A | E34: #N/A | F34: #N/A | G34: #N/A | H34: #N/A | I34: #N/A | J34: #N/A | K34: #N/A | L34: #N/A | M34: #N/A | N34: #N/A | O34: #N/A | P34: #N/A | Q34: #N/A | R34: #N/A | S34: #N/A | T34: #N/A | U34: #N/A | V34: #N/A | W34: #N/A | X34: #N/A | Y34: #N/A | Z34: #N/A | AA34: #N/A | AB34: #N/A | AC34: #N/A | AD34: #N/A | AE34: #N/A | AF34: #N/A | AG34: #N/A | AH34: #N/A | AI34: #N/A | AJ34: #N/A | AK34: #N/A | AL34: #N/A | AM34: #N/A | AN34: #N/A | AO34: #N/A | AP34: #N/A | AQ34: #N/A | AR34: #N/A | AS34: #N/A | AT34: #N/A | AU34: #N/A | AV34: #N/A | AW34: #N/A | AX34: #N/A | AY34: #N/A | AZ34: #N/A | BA34: #N/A | BB34: #N/A | BC34: #N/A | BD34: #N/A | BE34: #N/A | BF34: #N/A | BG34: #N/A | BH34: #N/A | BI34: #N/A | BJ34: #N/A | BK34: #N/A | BL34: #N/A | BM34: #N/A | BN34: #N/A | BO34: #N/A | BP34: #N/A | BQ34: #N/A | BR34: #N/A | BS34: #N/A | BT34: #N/A | BU34: #N/A | BV34: #N/A
A35: 9.2
A36: 9.3
A37: 9.4
A38: 10.1 | B38: HXT11 | C38: #N/A | D38: #N/A | E38: #N/A | F38: #N/A | G38: #N/A | H38: #N/A | I38: #N/A | J38: #N/A | K38: #N/A | L38: #N/A | M38: #N/A | N38: #N/A | O38: #N/A | P38: #N/A | Q38: #N/A | R38: #N/A | S38: #N/A | T38: #N/A | U38: #N/A | V38: #N/A | W38: #N/A | X38: #N/A | Y38: #N/A | Z38: #N/A | AA38: #N/A | AB38: #N/A | AC38: #N/A | AD38: #N/A | AE38: #N/A | AF38: #N/A | AG38: #N/A | AH38: #N/A | AI38: #N/A | AJ38: #N/A | AK38: #N/A | AL38: #N/A | AM38: #N/A | AN38: #N/A | AO38: #N/A | AP38: #N/A | AQ38: #N/A | AR38: #N/A | AS38: #N/A | AT38: #N/A | AU38: #N/A | AV38: #N/A | AW38: #N/A | AX38: #N/A | AY38: #N/A | AZ38: #N/A | BA38: #N/A | BB38: #N/A | BC38: #N/A | BD38: #N/A | BE38: #N/A | BF38: #N/A | BG38: #N/A | BH38: #N/A | BI38: #N/A | BJ38: #N/A | BK38: #N/A | BL38: #N/A | BM38: #N/A | BN38: #N/A | BO38: #N/A | BP38: #N/A | BQ38: #N/A | BR38: #N/A | BS38: #N/A | BT38: #N/A | BU38: #N/A | BV38: #N/A
A39: 10.2
A40: 10.3
...

Sheet Sheet2
A1: 1.1 | B1: HXT1 | C1: =PROPER(B1) -> Hxt1 | D1: =Sheet3!C2 -> 204.51169 | E1: =Sheet3!D2 -> 251.76499 | F1: =Sheet3!E2 -> 299.01829 | V1: =Sheet3!AM2 -> 148.68883 | W1: =Sheet3!AN2 -> 273.16392 | X1: =Sheet3!AO2 -> 397.63901 | Y1: =Sheet3!AP2 -> 0 | Z1: =Sheet3!AQ2 -> 0 | AA1: =Sheet3!AR2 -> 0 | AB1: =Sheet3!BB2 -> -38.376494 | AC1: =Sheet3!BC2 -> 52.423266 | AD1: =Sheet3!BD2 -> 143.22303 | AE1: =Sheet3!BE2 -> 0 | AF1: =Sheet3!BF2 -> 0 | AG1: =Sheet3!BG2 -> 0
A2: 1.2 | D2: =Sheet3!F2 -> 0 | E2: =Sheet3!G2 -> 0 | F2: =Sheet3!H2 -> 0 | Y2: =Sheet3!AS2 -> 0 | Z2: =Sheet3!AT2 -> 0 | AA2: =Sheet3!AU2 -> 0 | AE2: =Sheet3!BH2 -> 0 | AF2: =Sheet3!BI2 -> 0 | AG2: =Sheet3!BJ2 -> 0
A3: 1.3 | G3: =Sheet3!I2 -> -44.009784 | H3: =Sheet3!J2 -> 60.118483 | I3: =Sheet3!K2 -> 164.24675 | J3: =Sheet3!O2 -> 0 | K3: =Sheet3!P2 -> 0 | L3: =Sheet3!Q2 -> 0 | M3: =Sheet3!U2 -> 0 | N3: =Sheet3!V2 -> 0 | O3: =Sheet3!W2 -> 0 | P3: =Sheet3!AA2 -> 289.45426 | Q3: =Sheet3!AB2 -> 359.34922 | R3: =Sheet3!AC2 -> 429.24417 | S3: =Sheet3!AG2 -> 394.31522 | T3: =Sheet3!AH2 -> 448.82894 | U3: =Sheet3!AI2 -> 503.34266 | Y3: =Sheet3!AV2 -> 0 | Z3: =Sheet3!AW2 -> 0 | AA3: =Sheet3!AX2 -> 0 | AE3: =Sheet3!BK2 -> -10.536439 | AF3: =Sheet3!BL2 -> 14.393043 | AG3: =Sheet3!BM2 -> 39.322526 | AH3: =Sheet3!BT2 -> 0 | AI3: =Sheet3!BU2 -> 0 | AJ3: =Sheet3!BV2 -> 0
A4: 1.4 | G4: =Sheet3!L2 -> -84.71704 | H4: =Sheet3!M2 -> 115.72563 | I4: =Sheet3!N2 -> 316.1683 | J4: =Sheet3!R2 -> -45.775575 | K4: =Sheet3!S2 -> 62.530598 | L4: =Sheet3!T2 -> 170.83677 | M4: =Sheet3!X2 -> -21.952928 | N4: =Sheet3!Y2 -> 29.988258 | O4: =Sheet3!Z2 -> 81.929444 | P4: =Sheet3!AD2 -> 303.38493 | Q4: =Sheet3!AE2 -> 378.39408 | R4: =Sheet3!AF2 -> 453.40323 | S4: =Sheet3!AJ2 -> 246.17376 | T4: =Sheet3!AK2 -> 353.31957 | U4: =Sheet3!AL2 -> 460.46539 | Y4: =Sheet3!AY2 -> 0 | Z4: =Sheet3!AZ2 -> 0 | AA4: =Sheet3!BA2 -> 0 | AE4: =Sheet3!BN2 -> 0 | AF4: =Sheet3!BO2 -> 0 | AG4: =Sheet3!BP2 -> 0 | AH4: =Sheet3!BT2 -> 0 | AI4: =Sheet3!BU2 -> 0 | AJ4: =Sheet3!BV2 -> 0
A5: 2.1 | B5: HXT2 | C5: =PROPER(B5) -> Hxt2 | D5: =Sheet3!C6 -> 48.648133 | E5: =Sheet3!D6 -> 59.659029 | F5: =Sheet3!E6 -> 70.669925 | V5: =Sheet3!AM6 -> 157.55821 | W5: =Sheet3!AN6 -> 181.44303 | X5: =Sheet3!AO6 -> 205.32785 | Y5: =Sheet3!AP6 -> 321.99507 | Z5: =Sheet3!AQ6 -> 408.50088 | AA5: =Sheet3!AR6 -> 495.0067 | AB5: =Sheet3!BB6 -> 55.341659 | AC5: =Sheet3!BC6 -> 158.24414 | AD5: =Sheet3!BD6 -> 261.14661 | AE5: =Sheet3!BE6 -> 370.9548 | AF5: =Sheet3!BF6 -> 404.5454 | AG5: =Sheet3!BG6 -> 438.13601
A6: 2.2 | D6: =Sheet3!F6 -> 24.717593 | E6: =Sheet3!G6 -> 37.739009 | F6: =Sheet3!H6 -> 50.760426 | Y6: =Sheet3!AS6 -> 62.784541 | Z6: =Sheet3!AT6 -> 63.690868 | AA6: =Sheet3!AU6 -> 64.597195 | AE6: =Sheet3!BH6 -> 183.40913 | AF6: =Sheet3!BI6 -> 235.37241 | AG6: =Sheet3!BJ6 -> 287.33568
A7: 2.3 | G7: =Sheet3!I6 -> 76.9948 | H7: =Sheet3!J6 -> 86.886682 | I7: =Sheet3!K6 -> 96.778565 | J7: =Sheet3!O6 -> 21.673666 | K7: =Sheet3!P6 -> 29.723328 | L7: =Sheet3!Q6 -> 37.77299 | M7: =Sheet3!U6 -> 23.101594 | N7: =Sheet3!V6 -> 32.569465 | O7: =Sheet3!W6 -> 42.037335 | P7: =Sheet3!AA6 -> 39.31734 | Q7: =Sheet3!AB6 -> 65.77888 | R7: =Sheet3!AC6 -> 92.24042 | S7: =Sheet3!AG6 -> 17.297532 | T7: =Sheet3!AH6 -> 35.181708 | U7: =Sheet3!AI6 -> 53.065885 | Y7: =Sheet3!AV6 -> 15.502828 | Z7: =Sheet3!AW6 -> 17.519952 | AA7: =Sheet3!AX6 -> 19.537075 | AE7: =Sheet3!BK6 -> 154.14608 | AF7: =Sheet3!BL6 -> 176.29131 | AG7: =Sheet3!BM6 -> 198.43653 | AH7: =Sheet3!BT6 -> 11.977355 | AI7: =Sheet3!BU6 -> 13.968968 | AJ7: =Sheet3!BV6 -> 15.960581
A8: 2.4 | G8: =Sheet3!L6 -> 33.150849 | H8: =Sheet3!M6 -> 81.273091 | I8: =Sheet3!N6 -> 129.39533 | J8: =Sheet3!R6 -> 13.12194 | K8: =Sheet3!S6 -> 26.568689 | L8: =Sheet3!T6 -> 40.015439 | M8: =Sheet3!X6 -> 24.117067 | N8: =Sheet3!Y6 -> 32.79338 | O8: =Sheet3!Z6 -> 41.469694 | P8: =Sheet3!AD6 -> 30.274016 | Q8: =Sheet3!AE6 -> 31.213996 | R8: =Sheet3!AF6 -> 32.153977 | S8: =Sheet3!AJ6 -> 4.0562377 | T8: =Sheet3!AK6 -> 31.728172 | U8: =Sheet3!AL6 -> 59.400107 | Y8: =Sheet3!AY6 -> 12.796062 | Z8: =Sheet3!AZ6 -> 24.747721 | AA8: =Sheet3!BA6 -> 36.69938 | AE8: =Sheet3!BN6 -> 108.35082 | AF8: =Sheet3!BO6 -> 140.94398 | AG8: =Sheet3!BP6 -> 173.53714 | AH8: =Sheet3!BT6 -> 11.977355 | AI8: =Sheet3!BU6 -> 13.968968 | AJ8: =Sheet3!BV6 -> 15.960581
A9: 3.1 | B9: HXT3 | C9: =PROPER(B9) -> Hxt3 | D9: =Sheet3!C10 -> 76.914903 | E9: =Sheet3!D10 -> 81.182226 | F9: =Sheet3!E10 -> 85.449548 | V9: =Sheet3!AM10 -> 59.110171 | W9: =Sheet3!AN10 -> 71.05307 | X9: =Sheet3!AO10 -> 82.995969 | Y9: =Sheet3!AP10 -> 36.904461 | Z9: =Sheet3!AQ10 -> 45.632524 | AA9: =Sheet3!AR10 -> 54.360586 | AB9: =Sheet3!BB10 -> 92.61711 | AC9: =Sheet3!BC10 -> 101.80664 | AD9: =Sheet3!BD10 -> 110.99618 | AE9: =Sheet3!BE10 -> 91.054782 | AF9: =Sheet3!BF10 -> 112.23934 | AG9: =Sheet3!BG10 -> 133.42389
A10: 3.2 | D10: =Sheet3!F10 -> 18.509349 | E10: =Sheet3!G10 -> 24.437712 | F10: =Sheet3!H10 -> 30.366075 | Y10: =Sheet3!AS10 -> -6.2751597 | Z10: =Sheet3!AT10 -> 13.272903 | AA10: =Sheet3!AU10 -> 32.820966 | AE10: =Sheet3!BH10 -> 56.182511 | AF10: =Sheet3!BI10 -> 61.448163 | AG10: =Sheet3!BJ10 -> 66.713814
A11: 3.3 | G11: =Sheet3!I10 -> 220.09613 | H11: =Sheet3!J10 -> 265.19689 | I11: =Sheet3!K10 -> 310.29766 | J11: =Sheet3!O10 -> 22.54549 | K11: =Sheet3!P10 -> 71.902265 | L11: =Sheet3!Q10 -> 121.25904 | M11: =Sheet3!U10 -> 67.826884 | N11: =Sheet3!V10 -> 87.674002 | O11: =Sheet3!W10 -> 107.52112 | P11: =Sheet3!AA10 -> 366.47714 | Q11: =Sheet3!AB10 -> 481.86492 | R11: =Sheet3!AC10 -> 597.25271 | S11: =Sheet3!AG10 -> 95.27141 | T11: =Sheet3!AH10 -> 103.36191 | U11: =Sheet3!AI10 -> 111.45241 | Y11: =Sheet3!AV10 -> 1.2103245 | Z11: =Sheet3!AW10 -> 36.105411 | AA11: =Sheet3!AX10 -> 71.000497 | AE11: =Sheet3!BK10 -> 16.348732 | AF11: =Sheet3!BL10 -> 23.438472 | AG11: =Sheet3!BM10 -> 30.528212 | AH11: =Sheet3!BT10 -> 12.192645 | AI11: =Sheet3!BU10 -> 22.415833 | AJ11: =Sheet3!BV10 -> 32.639021
A12: 3.4 | G12: =Sheet3!L10 -> 134.76125 | H12: =Sheet3!M10 -> 261.47164 | I12: =Sheet3!N10 -> 388.18202 | J12: =Sheet3!R10 -> 30.860971 | K12: =Sheet3!S10 -> 51.374871 | L12: =Sheet3!T10 -> 71.888771 | M12: =Sheet3!X10 -> 42.278365 | N12: =Sheet3!Y10 -> 61.257713 | O12: =Sheet3!Z10 -> 80.237062 | P12: =Sheet3!AD10 -> 190.66402 | Q12: =Sheet3!AE10 -> 288.10522 | R12: =Sheet3!AF10 -> 385.54642 | S12: =Sheet3!AJ10 -> 55.509069 | T12: =Sheet3!AK10 -> 61.271652 | U12: =Sheet3!AL10 -> 67.034236 | Y12: =Sheet3!AY10 -> 0.41763931 | Z12: =Sheet3!AZ10 -> 7.4648901 | AA12: =Sheet3!BA10 -> 14.512141 | AE12: =Sheet3!BN10 -> 32.079343 | AF12: =Sheet3!BO10 -> 36.36415 | AG12: =Sheet3!BP10 -> 40.648956 | AH12: =Sheet3!BT10 -> 12.192645 | AI12: =Sheet3!BU10 -> 22.415833 | AJ12: =Sheet3!BV10 -> 32.639021
A13: 4.1 | B13: HXT4 | C13: =PROPER(B13) -> Hxt4 | D13: =Sheet3!C14 -> 70.91079 | E13: =Sheet3!D14 -> 75.811643 | F13: =Sheet3!E14 -> 80.712496 | V13: =Sheet3!AM14 -> 131.52568 | W13: =Sheet3!AN14 -> 164.09176 | X13: =Sheet3!AO14 -> 196.65783 | Y13: =Sheet3!AP14 -> 84.664626 | Z13: =Sheet3!AQ14 -> 103.38199 | AA13: =Sheet3!AR14 -> 122.09935 | AB13: =Sheet3!BB14 -> 142.17103 | AC13: =Sheet3!BC14 -> 163.03225 | AD13: =Sheet3!BD14 -> 183.89347 | AE13: =Sheet3!BE14 -> 341.73005 | AF13: =Sheet3!BF14 -> 410.80779 | AG13: =Sheet3!BG14 -> 479.88553
A14: 4.2 | D14: =Sheet3!F14 -> -11.252874 | E14: =Sheet3!G14 -> 24.853552 | F14: =Sheet3!H14 -> 60.959979 | Y14: =Sheet3!AS14 -> 1.9740001 | Z14: =Sheet3!AT14 -> 15.359751 | AA14: =Sheet3!AU14 -> 28.745503 | AE14: =Sheet3!BH14 -> 131.97086 | AF14: =Sheet3!BI14 -> 137.12375 | AG14: =Sheet3!BJ14 -> 142.27663
A15: 4.3 | G15: =Sheet3!I14 -> 100.43082 | H15: =Sheet3!J14 -> 124.4074 | I15: =Sheet3!K14 -> 148.38398 | J15: =Sheet3!O14 -> 39.042794 | K15: =Sheet3!P14 -> 54.18848 | L15: =Sheet3!Q14 -> 69.334167 | M15: =Sheet3!U14 -> 39.277881 | N15: =Sheet3!V14 -> 67.6159 | O15: =Sheet3!W14 -> 95.95392 | P15: =Sheet3!AA14 -> 182.75981 | Q15: =Sheet3!AB14 -> 243.58393 | R15: =Sheet3!AC14 -> 304.40805 | S15: =Sheet3!AG14 -> 59.413456 | T15: =Sheet3!AH14 -> 71.110492 | U15: =Sheet3!AI14 -> 82.807528 | Y15: =Sheet3!AV14 -> 23.22073 | Z15: =Sheet3!AW14 -> 64.640297 | AA15: =Sheet3!AX14 -> 106.05986 | AE15: =Sheet3!BK14 -> 44.136144 | AF15: =Sheet3!BL14 -> 46.468664 | AG15: =Sheet3!BM14 -> 48.801184 | AH15: =Sheet3!BT14 -> 26.278607 | AI15: =Sheet3!BU14 -> 28.99771 | AJ15: =Sheet3!BV14 -> 31.716813
A16: 4.4 | G16: =Sheet3!L14 -> 68.207738 | H16: =Sheet3!M14 -> 175.14662 | I16: =Sheet3!N14 -> 282.08549 | J16: =Sheet3!R14 -> 7.6467786 | K16: =Sheet3!S14 -> 34.398196 | L16: =Sheet3!T14 -> 61.149614 | M16: =Sheet3!X14 -> -15.726632 | N16: =Sheet3!Y14 -> 21.482979 | O16: =Sheet3!Z14 -> 58.69259 | P16: =Sheet3!AD14 -> 111.53158 | Q16: =Sheet3!AE14 -> 131.07569 | R16: =Sheet3!AF14 -> 150.61979 | S16: =Sheet3!AJ14 -> 29.118784 | T16: =Sheet3!AK14 -> 30.603914 | U16: =Sheet3!AL14 -> 32.089045 | Y16: =Sheet3!AY14 -> 13.779977 | Z16: =Sheet3!AZ14 -> 21.723016 | AA16: =Sheet3!BA14 -> 29.666055 | AE16: =Sheet3!BN14 -> 119.87347 | AF16: =Sheet3!BO14 -> 137.97229 | AG16: =Sheet3!BP14 -> 156.07112 | AH16: =Sheet3!BT14 -> 26.278607 | AI16: =Sheet3!BU14 -> 28.99771 | AJ16: =Sheet3!BV14 -> 31.716813
A17: 5.1 | B17: HXT5 | C17: =PROPER(B17) -> Hxt5 | D17: =Sheet3!C18 -> 0 | E17: =Sheet3!D18 -> 0 | F17: =Sheet3!E18 -> 0 | V17: =Sheet3!AM18 -> 11.288068 | W17: =Sheet3!AN18 -> 14.538062 | X17: =Sheet3!AO18 -> 17.788055 | Y17: =Sheet3!AP18 -> 32.811534 | Z17: =Sheet3!AQ18 -> 37.154788 | AA17: =Sheet3!AR18 -> 41.498042 | AB17: =Sheet3!BB18 -> 6.5511616 | AC17: =Sheet3!BC18 -> 13.248578 | AD17: =Sheet3!BD18 -> 19.945994 | AE17: =Sheet3!BE18 -> 6.0646095 | AF17: =Sheet3!BF18 -> 14.752472 | AG17: =Sheet3!BG18 -> 23.440335
A18: 5.2 | D18: =Sheet3!F18 -> 72.712086 | E18: =Sheet3!G18 -> 96.940713 | F18: =Sheet3!H18 -> 121.16934 | Y18: =Sheet3!AS18 -> -4.1710168 | Z18: =Sheet3!AT18 -> 180.64711 | AA18: =Sheet3!AU18 -> 365.46523 | AE18: =Sheet3!BH18 -> 127.96373 | AF18: =Sheet3!BI18 -> 230.12623 | AG18: =Sheet3!BJ18 -> 332.28872
A19: 5.3 | G19: =Sheet3!I18 -> 174.90962 | H19: =Sheet3!J18 -> 259.3827 | I19: =Sheet3!K18 -> 343.85577 | J19: =Sheet3!O18 -> 49.052266 | K19: =Sheet3!P18 -> 124.51453 | L19: =Sheet3!Q18 -> 199.9768 | M19: =Sheet3!U18 -> 178.37044 | N19: =Sheet3!V18 -> 261.41531 | O19: =Sheet3!W18 -> 344.46018 | P19: =Sheet3!AA18 -> 36.549468 | Q19: =Sheet3!AB18 -> 41.603547 | R19: =Sheet3!AC18 -> 46.657626 | S19: =Sheet3!AG18 -> 19.576798 | T19: =Sheet3!AH18 -> 22.869813 | U19: =Sheet3!AI18 -> 26.162829 | Y19: =Sheet3!AV18 -> 51.924249 | Z19: =Sheet3!AW18 -> 106.74687 | AA19: =Sheet3!AX18 -> 161.5695 | AE19: =Sheet3!BK18 -> 370.49704 | AF19: =Sheet3!BL18 -> 389.46945 | AG19: =Sheet3!BM18 -> 408.44186 | AH19: =Sheet3!BT18 -> 76.688696 | AI19: =Sheet3!BU18 -> 81.165204 | AJ19: =Sheet3!BV18 -> 85.641712
A20: 5.4 | G20: =Sheet3!L18 -> 53.276979 | H20: =Sheet3!M18 -> 97.509631 | I20: =Sheet3!N18 -> 141.74228 | J20: =Sheet3!R18 -> 51.694195 | K20: =Sheet3!S18 -> 82.623092 | L20: =Sheet3!T18 -> 113.55199 | M20: =Sheet3!X18 -> 31.010272 | N20: =Sheet3!Y18 -> 69.938104 | O20: =Sheet3!Z18 -> 108.86594 | P20: =Sheet3!AD18 -> 0.6430057 | Q20: =Sheet3!AE18 -> 5.3444454 | R20: =Sheet3!AF18 -> 10.045885 | S20: =Sheet3!AJ18 -> 22.413737 | T20: =Sheet3!AK18 -> 24.232878 | U20: =Sheet3!AL18 -> 26.052019 | Y20: =Sheet3!AY18 -> 46.224013 | Z20: =Sheet3!AZ18 -> 59.595927 | AA20: =Sheet3!BA18 -> 72.967841 | AE20: =Sheet3!BN18 -> 57.234453 | AF20: =Sheet3!BO18 -> 65.51868 | AG20: =Sheet3!BP18 -> 73.802907 | AH20: =Sheet3!BT18 -> 76.688696 | AI20: =Sheet3!BU18 -> 81.165204 | AJ20: =Sheet3!BV18 -> 85.641712
A21: 6.1 | B21: HXT6 | C21: =PROPER(B21) -> Hxt6 | D21: =Sheet3!C22 -> 0 | E21: =Sheet3!D22 -> 0 | F21: =Sheet3!E22 -> 0 | V21: =Sheet3!AM22 -> 8.8378789 | W21: =Sheet3!AN22 -> 12.580469 | X21: =Sheet3!AO22 -> 16.32306 | Y21: =Sheet3!AP22 -> 212.25097 | Z21: =Sheet3!AQ22 -> 365.66314 | AA21: =Sheet3!AR22 -> 519.0753 | AB21: =Sheet3!BB22 -> 0.57793631 | AC21: =Sheet3!BC22 -> 5.135431 | AD21: =Sheet3!BD22 -> 9.6929258 | AE21: =Sheet3!BE22 -> 75.635906 | AF21: =Sheet3!BF22 -> 220.14468 | AG21: =Sheet3!BG22 -> 364.65346
A22: 6.2 | D22: =Sheet3!F22 -> -0.77867727 | E22: =Sheet3!G22 -> 3.7877519 | F22: =Sheet3!H22 -> 8.3541812 | Y22: =Sheet3!AS22 -> -36.844398 | Z22: =Sheet3!AT22 -> 74.93704 | AA22: =Sheet3!AU22 -> 186.71848 | AE22: =Sheet3!BH22 -> 240.46215 | AF22: =Sheet3!BI22 -> 510.30736 | AG22: =Sheet3!BJ22 -> 780.15256
A23: 6.3 | G23: =Sheet3!I22 -> 42.463768 | H23: =Sheet3!J22 -> 61.032882 | I23: =Sheet3!K22 -> 79.601995 | J23: =Sheet3!O22 -> -1.2705752 | K23: =Sheet3!P22 -> 1.735638 | L23: =Sheet3!Q22 -> 4.7418511 | M23: =Sheet3!U22 -> 1.8916577 | N23: =Sheet3!V22 -> 14.13429 | O23: =Sheet3!W22 -> 26.376923 | P23: =Sheet3!AA22 -> 75.74922 | Q23: =Sheet3!AB22 -> 218.58068 | R23: =Sheet3!AC22 -> 361.41213 | S23: =Sheet3!AG22 -> 0 | T23: =Sheet3!AH22 -> 0 | U23: =Sheet3!AI22 -> 0 | Y23: =Sheet3!AV22 -> 29.356056 | Z23: =Sheet3!AW22 -> 55.184949 | AA23: =Sheet3!AX22 -> 81.013843 | AE23: =Sheet3!BK22 -> 487.56655 | AF23: =Sheet3!BL22 -> 574.56862 | AG23: =Sheet3!BM22 -> 661.5707 | AH23: =Sheet3!BT22 -> 45.152406 | AI23: =Sheet3!BU22 -> 52.697245 | AJ23: =Sheet3!BV22 -> 60.242085
A24: 6.4 | G24: =Sheet3!L22 -> 19.671664 | H24: =Sheet3!M22 -> 40.698988 | I24: =Sheet3!N22 -> 61.726313 | J24: =Sheet3!R22 -> 0.85464506 | K24: =Sheet3!S22 -> 6.4930973 | L24: =Sheet3!T22 -> 12.13155 | M24: =Sheet3!X22 -> -0.42878468 | N24: =Sheet3!Y22 -> 0.58573077 | O24: =Sheet3!Z22 -> 1.6002462 | P24: =Sheet3!AD22 -> 19.36407 | Q24: =Sheet3!AE22 -> 57.459492 | R24: =Sheet3!AF22 -> 95.554914 | S24: =Sheet3!AJ22 -> 0 | T24: =Sheet3!AK22 -> 0 | U24: =Sheet3!AL22 -> 0 | Y24: =Sheet3!AY22 -> -3.6095688 | Z24: =Sheet3!AZ22 -> 18.634903 | AA24: =Sheet3!BA22 -> 40.879374 | AE24: =Sheet3!BN22 -> 70.692703 | AF24: =Sheet3!BO22 -> 83.77604 | AG24: =Sheet3!BP22 -> 96.859376 | AH24: =Sheet3!BT22 -> 45.152406 | AI24: =Sheet3!BU22 -> 52.697245 | AJ24: =Sheet3!BV22 -> 60.242085
A25: 7.1 | B25: HXT7 | C25: =PROPER(B25) -> Hxt7 | D25: =Sheet3!C26 -> 0 | E25: =Sheet3!D26 -> 0 | F25: =Sheet3!E26 -> 0 | V25: =Sheet3!AM26 -> 53.210173 | W25: =Sheet3!AN26 -> 76.039058 | X25: =Sheet3!AO26 -> 98.867944 | Y25: =Sheet3!AP26 -> 459.10156 | Z25: =Sheet3!AQ26 -> 570.60132 | AA25: =Sheet3!AR26 -> 682.10109 | AB25: =Sheet3!BB26 -> 30.554312 | AC25: =Sheet3!BC26 -> 50.746252 | AD25: =Sheet3!BD26 -> 70.938191 | AE25: =Sheet3!BE26 -> 226.58184 | AF25: =Sheet3!BF26 -> 418.95927 | AG25: =Sheet3!BG26 -> 611.3367
A26: 7.2 | D26: =Sheet3!F26 -> -0.57768729 | E26: =Sheet3!G26 -> 0.78913551 | F26: =Sheet3!H26 -> 2.1559583 | Y26: =Sheet3!AS26 -> -12.491611 | Z26: =Sheet3!AT26 -> 38.665336 | AA26: =Sheet3!AU26 -> 89.822283 | AE26: =Sheet3!BH26 -> 226.18249 | AF26: =Sheet3!BI26 -> 327.77615 | AG26: =Sheet3!BJ26 -> 429.36982
A27: 7.3 | G27: =Sheet3!I26 -> 35.184735 | H27: =Sheet3!J26 -> 44.633166 | I27: =Sheet3!K26 -> 54.081596 | J27: =Sheet3!O26 -> -1.9332041 | K27: =Sheet3!P26 -> 2.6408059 | L27: =Sheet3!Q26 -> 7.2148158 | M27: =Sheet3!U26 -> 6.4506923 | N27: =Sheet3!V26 -> 8.4039156 | O27: =Sheet3!W26 -> 10.357139 | P27: =Sheet3!AA26 -> 69.810459 | Q27: =Sheet3!AB26 -> 149.36115 | R27: =Sheet3!AC26 -> 228.91185 | S27: =Sheet3!AG26 -> -2.0100492 | T27: =Sheet3!AH26 -> 2.7457783 | U27: =Sheet3!AI26 -> 7.5016059 | Y27: =Sheet3!AV26 -> 16.936631 | Z27: =Sheet3!AW26 -> 36.201364 | AA27: =Sheet3!AX26 -> 55.466098 | AE27: =Sheet3!BK26 -> 301.32544 | AF27: =Sheet3!BL26 -> 366.85965 | AG27: =Sheet3!BM26 -> 432.39386 | AH27: =Sheet3!BT26 -> 10.968861 | AI27: =Sheet3!BU26 -> 17.368479 | AJ27: =Sheet3!BV26 -> 23.768097
A28: 7.4 | G28: =Sheet3!L26 -> 13.749028 | H28: =Sheet3!M26 -> 24.93879 | I28: =Sheet3!N26 -> 36.128552 | J28: =Sheet3!R26 -> 1.8795248 | K28: =Sheet3!S26 -> 6.9249128 | L28: =Sheet3!T26 -> 11.970301 | M28: =Sheet3!X26 -> -1.4948393 | N28: =Sheet3!Y26 -> 2.0419885 | O28: =Sheet3!Z26 -> 5.5788163 | P28: =Sheet3!AD26 -> 18.754109 | Q28: =Sheet3!AE26 -> 41.021921 | R28: =Sheet3!AF26 -> 63.289732 | S28: =Sheet3!AJ26 -> 0 | T28: =Sheet3!AK26 -> 0 | U28: =Sheet3!AL26 -> 0 | Y28: =Sheet3!AY26 -> 9.5448018 | Z28: =Sheet3!AZ26 -> 17.829207 | AA28: =Sheet3!BA26 -> 26.113611 | AE28: =Sheet3!BN26 -> 148.59464 | AF28: =Sheet3!BO26 -> 179.53678 | AG28: =Sheet3!BP26 -> 210.47892 | AH28: =Sheet3!BT26 -> 10.968861 | AI28: =Sheet3!BU26 -> 17.368479 | AJ28: =Sheet3!BV26 -> 23.768097
A29: 8.1 | B29: HXT8 | C29: =PROPER(B29) -> Hxt8 | D29: =Sheet3!C30 -> #N/A | E29: =Sheet3!D30 -> #N/A | F29: =Sheet3!E30 -> #N/A | V29: =Sheet3!AM30 -> #N/A | W29: =Sheet3!AN30 -> #N/A | X29: =Sheet3!AO30 -> #N/A | Y29: =Sheet3!AP30 -> #N/A | Z29: =Sheet3!AQ30 -> #N/A | AA29: =Sheet3!AR30 -> #N/A | AB29: =Sheet3!BB30 -> #N/A | AC29: =Sheet3!BC30 -> #N/A | AD29: =Sheet3!BD30 -> #N/A | AE29: =Sheet3!BE30 -> #N/A | AF29: =Sheet3!BF30 -> #N/A | AG29: =Sheet3!BG30 -> #N/A
A30: 8.2 | D30: =Sheet3!F30 -> #N/A | E30: =Sheet3!G30 -> #N/A | F30: =Sheet3!H30 -> #N/A | Y30: =Sheet3!AS30 -> #N/A | Z30: =Sheet3!AT30 -> #N/A | AA30: =Sheet3!AU30 -> #N/A | AE30: =Sheet3!BH30 -> #N/A | AF30: =Sheet3!BI30 -> #N/A | AG30: =Sheet3!BJ30 -> #N/A
A31: 8.3 | G31: =Sheet3!I30 -> #N/A | H31: =Sheet3!J30 -> #N/A | I31: =Sheet3!K30 -> #N/A | J31: =Sheet3!O30 -> #N/A | K31: =Sheet3!P30 -> #N/A | L31: =Sheet3!Q30 -> #N/A | M31: =Sheet3!U30 -> #N/A | N31: =Sheet3!V30 -> #N/A | O31: =Sheet3!W30 -> #N/A | P31: =Sheet3!AA30 -> #N/A | Q31: =Sheet3!AB30 -> #N/A | R31: =Sheet3!AC30 -> #N/A | S31: =Sheet3!AG30 -> #N/A | T31: =Sheet3!AH30 -> #N/A | U31: =Sheet3!AI30 -> #N/A | Y31: =Sheet3!AV30 -> #N/A | Z31: =Sheet3!AW30 -> #N/A | AA31: =Sheet3!AX30 -> #N/A | AE31: =Sheet3!BK30 -> #N/A | AF31: =Sheet3!BL30 -> #N/A | AG31: =Sheet3!BM30 -> #N/A | AH31: =Sheet3!BT30 -> #N/A | AI31: =Sheet3!BU30 -> #N/A | AJ31: =Sheet3!BV30 -> #N/A
A32: 8.4 | G32: =Sheet3!L30 -> #N/A | H32: =Sheet3!M30 -> #N/A | I32: =Sheet3!N30 -> #N/A | J32: =Sheet3!R30 -> #N/A | K32: =Sheet3!S30 -> #N/A | L32: =Sheet3!T30 -> #N/A | M32: =Sheet3!X30 -> #N/A | N32: =Sheet3!Y30 -> #N/A | O32: =Sheet3!Z30 -> #N/A | P32: =Sheet3!AD30 -> #N/A | Q32: =Sheet3!AE30 -> #N/A | R32: =Sheet3!AF30 -> #N/A | S32: =Sheet3!AJ30 -> #N/A | T32: =Sheet3!AK30 -> #N/A | U32: =Sheet3!AL30 -> #N/A | Y32: =Sheet3!AY30 -> #N/A | Z32: =Sheet3!AZ30 -> #N/A | AA32: =Sheet3!BA30 -> #N/A | AE32: =Sheet3!BN30 -> #N/A | AF32: =Sheet3!BO30 -> #N/A | AG32: =Sheet3!BP30 -> #N/A | AH32: =Sheet3!BT30 -> #N/A | AI32: =Sheet3!BU30 -> #N/A | AJ32: =Sheet3!BV30 -> #N/A
A33: 9.1 | B33: HXT10 | C33: =PROPER(B33) -> Hxt10 | D33: =Sheet3!C34 -> #N/A | E33: =Sheet3!D34 -> #N/A | F33: =Sheet3!E34 -> #N/A | V33: =Sheet3!AM34 -> #N/A | W33: =Sheet3!AN34 -> #N/A | X33: =Sheet3!AO34 -> #N/A | Y33: =Sheet3!AP34 -> #N/A | Z33: =Sheet3!AQ34 -> #N/A | AA33: =Sheet3!AR34 -> #N/A | AB33: =Sheet3!BB34 -> #N/A | AC33: =Sheet3!BC34 -> #N/A | AD33: =Sheet3!BD34 -> #N/A | AE33: =Sheet3!BE34 -> #N/A | AF33: =Sheet3!BF34 -> #N/A | AG33: =Sheet3!BG34 -> #N/A
A34: 9.2 | D34: =Sheet3!F34 -> #N/A | E34: =Sheet3!G34 -> #N/A | F34: =Sheet3!H34 -> #N/A | Y34: =Sheet3!AS34 -> #N/A | Z34: =Sheet3!AT34 -> #N/A | AA34: =Sheet3!AU34 -> #N/A | AE34: =Sheet3!BH34 -> #N/A | AF34: =Sheet3!BI34 -> #N/A | AG34: =Sheet3!BJ34 -> #N/A
A35: 9.3 | G35: =Sheet3!I34 -> #N/A | H35: =Sheet3!J34 -> #N/A | I35: =Sheet3!K34 -> #N/A | J35: =Sheet3!O34 -> #N/A | K35: =Sheet3!P34 -> #N/A | L35: =Sheet3!Q34 -> #N/A | M35: =Sheet3!U34 -> #N/A | N35: =Sheet3!V34 -> #N/A | O35: =Sheet3!W34 -> #N/A | P35: =Sheet3!AA34 -> #N/A | Q35: =Sheet3!AB34 -> #N/A | R35: =Sheet3!AC34 -> #N/A | S35: =Sheet3!AG34 -> #N/A | T35: =Sheet3!AH34 -> #N/A | U35: =Sheet3!AI34 -> #N/A | Y35: =Sheet3!AV34 -> #N/A | Z35: =Sheet3!AW34 -> #N/A | AA35: =Sheet3!AX34 -> #N/A | AE35: =Sheet3!BK34 -> #N/A | AF35: =Sheet3!BL34 -> #N/A | AG35: =Sheet3!BM34 -> #N/A | AH35: =Sheet3!BT34 -> #N/A | AI35: =Sheet3!BU34 -> #N/A | AJ35: =Sheet3!BV34 -> #N/A
A36: 9.4 | G36: =Sheet3!L34 -> #N/A | H36: =Sheet3!M34 -> #N/A | I36: =Sheet3!N34 -> #N/A | J36: =Sheet3!R34 -> #N/A | K36: =Sheet3!S34 -> #N/A | L36: =Sheet3!T34 -> #N/A | M36: =Sheet3!X34 -> #N/A | N36: =Sheet3!Y34 -> #N/A | O36: =Sheet3!Z34 -> #N/A | P36: =Sheet3!AD34 -> #N/A | Q36: =Sheet3!AE34 -> #N/A | R36: =Sheet3!AF34 -> #N/A | S36: =Sheet3!AJ34 -> #N/A | T36: =Sheet3!AK34 -> #N/A | U36: =Sheet3!AL34 -> #N/A | Y36: =Sheet3!AY34 -> #N/A | Z36: =Sheet3!AZ34 -> #N/A | AA36: =Sheet3!BA34 -> #N/A | AE36: =Sheet3!BN34 -> #N/A | AF36: =Sheet3!BO34 -> #N/A | AG36: =Sheet3!BP34 -> #N/A | AH36: =Sheet3!BT34 -> #N/A | AI36: =Sheet3!BU34 -> #N/A | AJ36: =Sheet3!BV34 -> #N/A
A37: 10.1 | B37: HXT11 | C37: =PROPER(B37) -> Hxt11 | D37: =Sheet3!C38 -> #N/A | E37: =Sheet3!D38 -> #N/A | F37: =Sheet3!E38 -> #N/A | V37: =Sheet3!AM38 -> #N/A | W37: =Sheet3!AN38 -> #N/A | X37: =Sheet3!AO38 -> #N/A | Y37: =Sheet3!AP38 -> #N/A | Z37: =Sheet3!AQ38 -> #N/A | AA37: =Sheet3!AR38 -> #N/A | AB37: =Sheet3!BB38 -> #N/A | AC37: =Sheet3!BC38 -> #N/A | AD37: =Sheet3!BD38 -> #N/A | AE37: =Sheet3!BE38 -> #N/A | AF37: =Sheet3!BF38 -> #N/A | AG37: =Sheet3!BG38 -> #N/A
A38: 10.2 | D38: =Sheet3!F38 -> #N/A | E38: =Sheet3!G38 -> #N/A | F38: =Sheet3!H38 -> #N/A | Y38: =Sheet3!AS38 -> #N/A | Z38: =Sheet3!AT38 -> #N/A | AA38: =Sheet3!AU38 -> #N/A | AE38: =Sheet3!BH38 -> #N/A | AF38: =Sheet3!BI38 -> #N/A | AG38: =Sheet3!BJ38 -> #N/A
A39: 10.3 | G39: =Sheet3!I38 -> #N/A | H39: =Sheet3!J38 -> #N/A | I39: =Sheet3!K38 -> #N/A | J39: =Sheet3!O38 -> #N/A | K39: =Sheet3!P38 -> #N/A | L39: =Sheet3!Q38 -> #N/A | M39: =Sheet3!U38 -> #N/A | N39: =Sheet3!V38 -> #N/A | O39: =Sheet3!W38 -> #N/A | P39: =Sheet3!AA38 -> #N/A | Q39: =Sheet3!AB38 -> #N/A | R39: =Sheet3!AC38 -> #N/A | S39: =Sheet3!AG38 -> #N/A | T39: =Sheet3!AH38 -> #N/A | U39: =Sheet3!AI38 -> #N/A | Y39: =Sheet3!AV38 -> #N/A | Z39: =Sheet3!AW38 -> #N/A | AA39: =Sheet3!AX38 -> #N/A | AE39: =Sheet3!BK38 -> #N/A | AF39: =Sheet3!BL38 -> #N/A | AG39: =Sheet3!BM38 -> #N/A | AH39: =Sheet3!BT38 -> #N/A | AI39: =Sheet3!BU38 -> #N/A | AJ39: =Sheet3!BV38 -> #N/A
A40: 10.4 | G40: =Sheet3!L38 -> #N/A | H40: =Sheet3!M38 -> #N/A | I40: =Sheet3!N38 -> #N/A | J40: =Sheet3!R38 -> #N/A | K40: =Sheet3!S38 -> #N/A | L40: =Sheet3!T38 -> #N/A | M40: =Sheet3!X38 -> #N/A | N40: =Sheet3!Y38 -> #N/A | O40: =Sheet3!Z38 -> #N/A | P40: =Sheet3!AD38 -> #N/A | Q40: =Sheet3!AE38 -> #N/A | R40: =Sheet3!AF38 -> #N/A | S40: =Sheet3!AJ38 -> #N/A | T40: =Sheet3!AK38 -> #N/A | U40: =Sheet3!AL38 -> #N/A | Y40: =Sheet3!AY38 -> #N/A | Z40: =Sheet3!AZ38 -> #N/A | AA40: =Sheet3!BA38 -> #N/A | AE40: =Sheet3!BN38 -> #N/A | AF40: =Sheet3!BO38 -> #N/A | AG40: =Sheet3!BP38 -> #N/A | AH40: =Sheet3!BT38 -> #N/A | AI40: =Sheet3!BU38 -> #N/A | AJ40: =Sheet3!BV38 -> #N/A
...
